<?xml version="1.0"?>
<robot xmlns:xacro="http://www.ros.org/wiki/xacro">
<!-- ##################################################################################################### -->

    <xacro:macro name="kukawheel" params="prefix">

        <link name="wheel_link_${prefix}">
            <visual>
                <geometry>
                    <mesh filename="package://kukabot_description/meshes/base/front-left_wheel.dae" />
                    <!-- <sphere radius="${wheel_radius}"/> -->
                </geometry>
                <origin xyz="0 0 0" rpy="0 0 0"/>
                <material name="Orange"/>
            </visual>

            <collision>
                <origin xyz="0 0 0" rpy="${M_PI/2} 0 0"/>
                <geometry>
                    <cylinder radius="${wheel_radius}" length="${wheel_radius}"/>
                </geometry>
            </collision>        
            <inertial>
                <mass value="${wheel_mass}"/>
                <origin xyz="0 0 0"/>
                <inertia ixx="0.012411765597" ixy="-0.000711733678" ixz="0.00050272983" 
                        iyy="0.015218160428" iyz="-0.000004273467" 
                        izz="0.011763977943"/>
            </inertial>
        </link>

        <joint name="wheel_joint_${prefix}" type="continuous">
            <parent link="caster_link_${prefix}"/>
            <child link="wheel_link_${prefix}"/>
            <origin xyz="${wheel_offset_x} ${wheel_offset_y} ${wheel_offset_z}" rpy="0 0 0"/>
            <axis xyz="0 1 0"/>

            <limit effort="${wheel_joint_effort}" velocity="${wheel_joint_velocity}"/>

            <dynamics damping="${wheel_joint_damping}" friction="${wheel_joint_friction}"/>

            <safety_controller k_velocity="${wheel_joint_safety_k_velocity}"/>
        </joint>

    </xacro:macro>

</robot>